Workbook

Sheet Work Items
A1: Key | B1: Type | C1: Epic | D1: Parent | E1: Work item | F1: Assignee | G1: Status | H1: Start | I1: Due | J1: Resolved | K1: Notes
A2: KAN-91 | B2: Epic | C2: Meetings | E2: Meetings | F2: Indiana Silbert | G2: Done | H2: 28/08/2026 | I2: 09/10/2026 | J2: 09/10/2026 | K2: Members required to be present: @Shakiba B @Sangjun Nam @Banyei Chan @Lincoln van Halen @Indiana Silbert
A3: KAN-102 | B3: Task | C3: Meetings | E3: Meetup on 28th in Library | F3: Indiana Silbert | G3: Done | H3: 28/09/2026 | I3: 28/09/2026 | J3: 28/09/2026 | K3: During Tuition-free week everyone attend: @Shakiba B @Sangjun Nam @Banyei Chan @Lincoln van Halen @Indiana Silbert
A4: KAN-104 | B4: Task | C4: Meetings | E4: Minutes | F4: Indiana Silbert | G4: Done | I4: 09/10/2026 | J4: 09/10/2026 | K4: @Indiana Silbert , please upload minutes to Google Doc after each meeting, thanks * 28/08 * 04/09 * 11/09 * 18/09 * 25/09 * 28/09 * 02/10 * 09/10
A5: KAN-135 | B5: Task | C5: Meetings | E5: Project Management | F5: Sangjun Nam | G5: Done | I5: 09/10/2026 | J5: 09/10/2026
A6: KAN-103 | B6: Subtask | C6: Meetings | D6: Meetup on 28th in Library | E6: Library Room Booking | F6: Indiana Silbert | G6: Done | J6: 28/09/2026 | K6: Need booking from 12-6 pm * 12-2 pm: @Indiana Silbert * 2-4 pm: @Sangjun Nam * 4-6 pm: @Lincoln van Halen
A7: KAN-136 | B7: Subtask | C7: Meetings | D7: Project Management | E7: Effort estimation (estimated hours) | F7: Shakiba B | G7: Done | J7: 09/10/2026
A8: KAN-137 | B8: Subtask | C8: Meetings | D8: Project Management | E8: Gantt chart | F8: Shakiba B | G8: Done | J8: 09/10/2026
A9: KAN-138 | B9: Subtask | C9: Meetings | D9: Project Management | E9: WBS | F9: Shakiba B | G9: Done | J9: 09/10/2026
A10: KAN-140 | B10: Subtask | C10: Meetings | D10: Project Management | E10: Weekly progress check or status update | F10: Indiana Silbert | G10: Done | J10: 09/10/2026
A11: KAN-76 | B11: Epic | C11: Application Setups | E11: Application Setups | F11: Lincoln van Halen | G11: Done | H11: 31/08/2026 | I11: 07/10/2026 | J11: 09/10/2026
A12: KAN-80 | B12: Task | C12: Application Setups | E12: GitHub | F12: Shakiba B | G12: Done | I12: 04/09/2026 | J12: 09/10/2026 | K12: Target date: 04/09
A13: KAN-81 | B13: Task | C13: Application Setups | E13: Jira | F13: Lincoln van Halen | G13: Done | I13: 04/09/2026 | J13: 09/10/2026 | K13: Target date: 04/09
A14: KAN-82 | B14: Task | C14: Application Setups | E14: Wazuh | F14: Lincoln van Halen | G14: Done | I14: 02/10/2026 | J14: 09/10/2026 | K14: Target date: 02/10
A15: KAN-84 | B15: Task | C15: Application Setups | E15: Google Docs | F15: Indiana Silbert | G15: Done | I15: 04/09/2026 | J15: 28/09/2026 | K15: Target date: 04/09
A16: KAN-87 | B16: Task | C16: Application Setups | E16: Virtual Machines | F16: Sangjun Nam | G16: Done | I16: 11/09/2026 | J16: 28/09/2026
A17: KAN-94 | B17: Task | C17: Application Setups | E17: Malicious Websites | F17: Sangjun Nam | G17: Done | I17: 02/10/2026 | J17: 09/10/2026
A18: KAN-100 | B18: Task | C18: Application Setups | E18: Apache | F18: Banyei Chan | G18: Done | I18: 11/09/2026 | J18: 09/10/2026 | K18: Target date: 11/09
A19: KAN-83 | B19: Subtask | C19: Application Setups | D19: GitHub | E19: Add all members | F19: Shakiba B | G19: Done | J19: 28/09/2026 | K19: Target date: 11/09
A20: KAN-86 | B20: Subtask | C20: Application Setups | D20: GitHub | E20: Upload CSRF Website | F20: Banyei Chan | G20: Done | J20: 09/10/2026 | K20: Target date: 28/09
A21: KAN-88 | B21: Subtask | C21: Application Setups | D21: Virtual Machines | E21: For Path Traversal | F21: Lincoln van Halen | G21: Done | J21: 28/09/2026 | K21: Target date: 11/09
A22: KAN-89 | B22: Subtask | C22: Application Setups | D22: Virtual Machines | E22: For CSRF (x2) | F22: Banyei Chan | G22: Done | J22: 28/09/2026 | K22: @Banyei Chan @Sangjun Nam 04/09
A23: KAN-95 | B23: Subtask | C23: Application Setups | D23: Malicious Websites | E23: Path Traversal Web Servers | F23: Lincoln van Halen | G23: Done | J23: 09/10/2026 | K23: * HTTP/GET Request * Track using Wireshark
A24: KAN-96 | B24: Subtask | C24: Application Setups | D24: Malicious Websites | E24: CSRF | F24: Banyei Chan | G24: Done | J24: 09/10/2026 | K24: * Anyone should be able to log in * Logged in user then visits a separate website with malicious Code * Authentication Session Token is passed from the two websites by the browser
A25: KAN-113 | B25: Subtask | C25: Application Setups | D25: Jira | E25: Jira Organisation | F25: Shakiba B | G25: Done | J25: 09/10/2026
A26: KAN-42 | B26: Epic | C26: Research | E26: Research | F26: Banyei Chan | G26: Done | I26: 29/09/2026 | J26: 09/10/2026
A27: KAN-92 | B27: Task | C27: Research | E27: CSRF | F27: Banyei Chan | G27: Done | I27: 28/09/2026 | J27: 09/10/2026 | K27: @Shakiba B @Banyei Chan @Indiana Silbert
A28: KAN-93 | B28: Task | C28: Research | E28: Path Traversal | F28: Indiana Silbert | G28: Done | I28: 29/09/2026 | J28: 09/10/2026
A29: KAN-97 | B29: Subtask | C29: Research | D29: CSRF | E29: Mitigation Strategies | F29: Banyei Chan | G29: Done | J29: 09/10/2026 | K29: Target date: 18/09
A30: KAN-98 | B30: Subtask | C30: Research | D30: CSRF | E30: Vulnerability Exploitation | F30: Banyei Chan | G30: Done | J30: 09/10/2026 | K30: Due on the 18/09
A31: KAN-99 | B31: Subtask | C31: Research | D31: CSRF | E31: Vulnerability Identification and Explanation | F31: Banyei Chan | G31: Done | J31: 09/10/2026 | K31: Due on the 04/09
A32: KAN-105 | B32: Subtask | C32: Research | D32: CSRF | E32: Impact on Confidentiality, Availability, and Integrity | F32: Shakiba B | G32: Done | J32: 09/10/2026 | K32: Target date: 28/09
A33: KAN-106 | B33: Subtask | C33: Research | D33: Path Traversal | E33: Impact on Confidentiality, Availability, and Integrity | F33: Indiana Silbert | G33: Done | J33: 09/10/2026 | K33: Target date: 11/09
A34: KAN-107 | B34: Subtask | C34: Research | D34: Path Traversal | E34: Vulnerability Identification and Explanation | F34: Indiana Silbert | G34: Done | J34: 09/10/2026 | K34: Target date: 11/09
A35: KAN-108 | B35: Subtask | C35: Research | D35: Path Traversal | E35: Vulnerability Exploitation | F35: Indiana Silbert | G35: Done | J35: 09/10/2026 | K35: Target date: 04/09
A36: KAN-109 | B36: Subtask | C36: Research | D36: Path Traversal | E36: Mitigation Strategies | F36: Indiana Silbert | G36: Done | J36: 09/10/2026 | K36: Target date: 18/09
A37: KAN-115 | B37: Subtask | C37: Research | D37: CSRF | E37: Why this vulnerability is common or significant (real-world examples, OWASP ranking) | F37: Shakiba B | G37: Done | J37: 09/10/2026
A38: KAN-116 | B38: Subtask | C38: Research | D38: Path Traversal | E38: Why this vulnerability is common or significant (real-world examples, OWASP ranking) | F38: Lincoln van Halen | G38: Done | J38: 09/10/2026
A39: KAN-117 | B39: Subtask | C39: Research | D39: Path Traversal | E39: Step-by-step explanation of the exploit | F39: Lincoln van Halen | G39: Done | J39: 09/10/2026
A40: KAN-118 | B40: Subtask | C40: Research | D40: CSRF | E40: Step-by-step explanation of the exploit | F40: Sangjun Nam | G40: Done | J40: 09/10/2026
...

Sheet Summary
A1: Jira work items by epic and status
A2: Counts tasks and subtasks (epics excluded). Calculated from the Work Items sheet.
A4: Epic | B4: To Do | C4: Planned | D4: In Progress | E4: Done | F4: Total | G4: % Done
A5: Meetings | B5: =COUNTIFS('Work Items'!$C$2:$C$84,$A5,'Work Items'!$G$2:$G$84,B$4,'Work Items'!$B$2:$B$84,"<>Epic") -> 0 | C5: =COUNTIFS('Work Items'!$C$2:$C$84,$A5,'Work Items'!$G$2:$G$84,C$4,'Work Items'!$B$2:$B$84,"<>Epic") -> 0 | D5: =COUNTIFS('Work Items'!$C$2:$C$84,$A5,'Work Items'!$G$2:$G$84,D$4,'Work Items'!$B$2:$B$84,"<>Epic") -> 0 | E5: =COUNTIFS('Work Items'!$C$2:$C$84,$A5,'Work Items'!$G$2:$G$84,E$4,'Work Items'!$B$2:$B$84,"<>Epic") -> 8 | F5: =SUM(B5:E5) -> 8 | G5: =IF(F5=0,0,E5/F5) -> 1
A6: Application Setups | B6: =COUNTIFS('Work Items'!$C$2:$C$84,$A6,'Work Items'!$G$2:$G$84,B$4,'Work Items'!$B$2:$B$84,"<>Epic") -> 0 | C6: =COUNTIFS('Work Items'!$C$2:$C$84,$A6,'Work Items'!$G$2:$G$84,C$4,'Work Items'!$B$2:$B$84,"<>Epic") -> 0 | D6: =COUNTIFS('Work Items'!$C$2:$C$84,$A6,'Work Items'!$G$2:$G$84,D$4,'Work Items'!$B$2:$B$84,"<>Epic") -> 0 | E6: =COUNTIFS('Work Items'!$C$2:$C$84,$A6,'Work Items'!$G$2:$G$84,E$4,'Work Items'!$B$2:$B$84,"<>Epic") -> 14 | F6: =SUM(B6:E6) -> 14 | G6: =IF(F6=0,0,E6/F6) -> 1
A7: Research | B7: =COUNTIFS('Work Items'!$C$2:$C$84,$A7,'Work Items'!$G$2:$G$84,B$4,'Work Items'!$B$2:$B$84,"<>Epic") -> 0 | C7: =COUNTIFS('Work Items'!$C$2:$C$84,$A7,'Work Items'!$G$2:$G$84,C$4,'Work Items'!$B$2:$B$84,"<>Epic") -> 0 | D7: =COUNTIFS('Work Items'!$C$2:$C$84,$A7,'Work Items'!$G$2:$G$84,D$4,'Work Items'!$B$2:$B$84,"<>Epic") -> 0 | E7: =COUNTIFS('Work Items'!$C$2:$C$84,$A7,'Work Items'!$G$2:$G$84,E$4,'Work Items'!$B$2:$B$84,"<>Epic") -> 14 | F7: =SUM(B7:E7) -> 14 | G7: =IF(F7=0,0,E7/F7) -> 1
A8: Development | B8: =COUNTIFS('Work Items'!$C$2:$C$84,$A8,'Work Items'!$G$2:$G$84,B$4,'Work Items'!$B$2:$B$84,"<>Epic") -> 10 | C8: =COUNTIFS('Work Items'!$C$2:$C$84,$A8,'Work Items'!$G$2:$G$84,C$4,'Work Items'!$B$2:$B$84,"<>Epic") -> 0 | D8: =COUNTIFS('Work Items'!$C$2:$C$84,$A8,'Work Items'!$G$2:$G$84,D$4,'Work Items'!$B$2:$B$84,"<>Epic") -> 0 | E8: =COUNTIFS('Work Items'!$C$2:$C$84,$A8,'Work Items'!$G$2:$G$84,E$4,'Work Items'!$B$2:$B$84,"<>Epic") -> 0 | F8: =SUM(B8:E8) -> 10 | G8: =IF(F8=0,0,E8/F8) -> 0
A9: Detection and Tracing | B9: =COUNTIFS('Work Items'!$C$2:$C$84,$A9,'Work Items'!$G$2:$G$84,B$4,'Work Items'!$B$2:$B$84,"<>Epic") -> 5 | C9: =COUNTIFS('Work Items'!$C$2:$C$84,$A9,'Work Items'!$G$2:$G$84,C$4,'Work Items'!$B$2:$B$84,"<>Epic") -> 0 | D9: =COUNTIFS('Work Items'!$C$2:$C$84,$A9,'Work Items'!$G$2:$G$84,D$4,'Work Items'!$B$2:$B$84,"<>Epic") -> 0 | E9: =COUNTIFS('Work Items'!$C$2:$C$84,$A9,'Work Items'!$G$2:$G$84,E$4,'Work Items'!$B$2:$B$84,"<>Epic") -> 0 | F9: =SUM(B9:E9) -> 5 | G9: =IF(F9=0,0,E9/F9) -> 0
A10: Testing and QA | B10: =COUNTIFS('Work Items'!$C$2:$C$84,$A10,'Work Items'!$G$2:$G$84,B$4,'Work Items'!$B$2:$B$84,"<>Epic") -> 1 | C10: =COUNTIFS('Work Items'!$C$2:$C$84,$A10,'Work Items'!$G$2:$G$84,C$4,'Work Items'!$B$2:$B$84,"<>Epic") -> 0 | D10: =COUNTIFS('Work Items'!$C$2:$C$84,$A10,'Work Items'!$G$2:$G$84,D$4,'Work Items'!$B$2:$B$84,"<>Epic") -> 0 | E10: =COUNTIFS('Work Items'!$C$2:$C$84,$A10,'Work Items'!$G$2:$G$84,E$4,'Work Items'!$B$2:$B$84,"<>Epic") -> 4 | F10: =SUM(B10:E10) -> 5 | G10: =IF(F10=0,0,E10/F10) -> 0.8
A11: Report | B11: =COUNTIFS('Work Items'!$C$2:$C$84,$A11,'Work Items'!$G$2:$G$84,B$4,'Work Items'!$B$2:$B$84,"<>Epic") -> 0 | C11: =COUNTIFS('Work Items'!$C$2:$C$84,$A11,'Work Items'!$G$2:$G$84,C$4,'Work Items'!$B$2:$B$84,"<>Epic") -> 0 | D11: =COUNTIFS('Work Items'!$C$2:$C$84,$A11,'Work Items'!$G$2:$G$84,D$4,'Work Items'!$B$2:$B$84,"<>Epic") -> 8 | E11: =COUNTIFS('Work Items'!$C$2:$C$84,$A11,'Work Items'!$G$2:$G$84,E$4,'Work Items'!$B$2:$B$84,"<>Epic") -> 4 | F11: =SUM(B11:E11) -> 12 | G11: =IF(F11=0,0,E11/F11) -> 0.33333333
A12: Presentation | B12: =COUNTIFS('Work Items'!$C$2:$C$84,$A12,'Work Items'!$G$2:$G$84,B$4,'Work Items'!$B$2:$B$84,"<>Epic") -> 0 | C12: =COUNTIFS('Work Items'!$C$2:$C$84,$A12,'Work Items'!$G$2:$G$84,C$4,'Work Items'!$B$2:$B$84,"<>Epic") -> 6 | D12: =COUNTIFS('Work Items'!$C$2:$C$84,$A12,'Work Items'!$G$2:$G$84,D$4,'Work Items'!$B$2:$B$84,"<>Epic") -> 0 | E12: =COUNTIFS('Work Items'!$C$2:$C$84,$A12,'Work Items'!$G$2:$G$84,E$4,'Work Items'!$B$2:$B$84,"<>Epic") -> 1 | F12: =SUM(B12:E12) -> 7 | G12: =IF(F12=0,0,E12/F12) -> 0.14285714
A13: Total | B13: =SUM(B5:B12) -> 16 | C13: =SUM(C5:C12) -> 6 | D13: =SUM(D5:D12) -> 8 | E13: =SUM(E5:E12) -> 45 | F13: =SUM(F5:F12) -> 75 | G13: =IF(F13=0,0,E13/F13) -> 0.6
A15: Work items by assignee
A16: Assignee | B16: To Do | C16: Planned | D16: In Progress | E16: Done | F16: Total
A17: Banyei Chan | B17: =COUNTIFS('Work Items'!$F$2:$F$84,$A17,'Work Items'!$G$2:$G$84,B$16,'Work Items'!$B$2:$B$84,"<>Epic") -> 5 | C17: =COUNTIFS('Work Items'!$F$2:$F$84,$A17,'Work Items'!$G$2:$G$84,C$16,'Work Items'!$B$2:$B$84,"<>Epic") -> 0 | D17: =COUNTIFS('Work Items'!$F$2:$F$84,$A17,'Work Items'!$G$2:$G$84,D$16,'Work Items'!$B$2:$B$84,"<>Epic") -> 1 | E17: =COUNTIFS('Work Items'!$F$2:$F$84,$A17,'Work Items'!$G$2:$G$84,E$16,'Work Items'!$B$2:$B$84,"<>Epic") -> 8 | F17: =SUM(B17:E17) -> 14
A18: Indiana Silbert | B18: =COUNTIFS('Work Items'!$F$2:$F$84,$A18,'Work Items'!$G$2:$G$84,B$16,'Work Items'!$B$2:$B$84,"<>Epic") -> 2 | C18: =COUNTIFS('Work Items'!$F$2:$F$84,$A18,'Work Items'!$G$2:$G$84,C$16,'Work Items'!$B$2:$B$84,"<>Epic") -> 2 | D18: =COUNTIFS('Work Items'!$F$2:$F$84,$A18,'Work Items'!$G$2:$G$84,D$16,'Work Items'!$B$2:$B$84,"<>Epic") -> 1 | E18: =COUNTIFS('Work Items'!$F$2:$F$84,$A18,'Work Items'!$G$2:$G$84,E$16,'Work Items'!$B$2:$B$84,"<>Epic") -> 12 | F18: =SUM(B18:E18) -> 17
A19: Lincoln van Halen | B19: =COUNTIFS('Work Items'!$F$2:$F$84,$A19,'Work Items'!$G$2:$G$84,B$16,'Work Items'!$B$2:$B$84,"<>Epic") -> 5 | C19: =COUNTIFS('Work Items'!$F$2:$F$84,$A19,'Work Items'!$G$2:$G$84,C$16,'Work Items'!$B$2:$B$84,"<>Epic") -> 1 | D19: =COUNTIFS('Work Items'!$F$2:$F$84,$A19,'Work Items'!$G$2:$G$84,D$16,'Work Items'!$B$2:$B$84,"<>Epic") -> 2 | E19: =COUNTIFS('Work Items'!$F$2:$F$84,$A19,'Work Items'!$G$2:$G$84,E$16,'Work Items'!$B$2:$B$84,"<>Epic") -> 7 | F19: =SUM(B19:E19) -> 15
A20: Sangjun Nam | B20: =COUNTIFS('Work Items'!$F$2:$F$84,$A20,'Work Items'!$G$2:$G$84,B$16,'Work Items'!$B$2:$B$84,"<>Epic") -> 4 | C20: =COUNTIFS('Work Items'!$F$2:$F$84,$A20,'Work Items'!$G$2:$G$84,C$16,'Work Items'!$B$2:$B$84,"<>Epic") -> 0 | D20: =COUNTIFS('Work Items'!$F$2:$F$84,$A20,'Work Items'!$G$2:$G$84,D$16,'Work Items'!$B$2:$B$84,"<>Epic") -> 2 | E20: =COUNTIFS('Work Items'!$F$2:$F$84,$A20,'Work Items'!$G$2:$G$84,E$16,'Work Items'!$B$2:$B$84,"<>Epic") -> 6 | F20: =SUM(B20:E20) -> 12
A21: Shakiba B | B21: =COUNTIFS('Work Items'!$F$2:$F$84,$A21,'Work Items'!$G$2:$G$84,B$16,'Work Items'!$B$2:$B$84,"<>Epic") -> 0 | C21: =COUNTIFS('Work Items'!$F$2:$F$84,$A21,'Work Items'!$G$2:$G$84,C$16,'Work Items'!$B$2:$B$84,"<>Epic") -> 3 | D21: =COUNTIFS('Work Items'!$F$2:$F$84,$A21,'Work Items'!$G$2:$G$84,D$16,'Work Items'!$B$2:$B$84,"<>Epic") -> 2 | E21: =COUNTIFS('Work Items'!$F$2:$F$84,$A21,'Work Items'!$G$2:$G$84,E$16,'Work Items'!$B$2:$B$84,"<>Epic") -> 12 | F21: =SUM(B21:E21) -> 17
A24: Source: Jira CSV export, 09/10/2026. Excluded: work items created in error and labelled for deletion ("DEL"), and one duplicate Testing epic. Account IDs replaced with member names; dates shown as DD/MM/YYYY.
